test004.c:8: エラー: `X' が再宣言されています.
test004.c:7: エラー: ここで宣言されていました.
test004.c:11: エラー: `S' が再宣言されています.
test004.c:10: エラー: ここで宣言されていました.
test004.c:11: エラー: `a' が再宣言されています.
test004.c:10: エラー: ここで宣言されていました.
test004.c:13: エラー: `a' が再宣言されています.
test004.c:13: エラー: ここで宣言されていました.
test004.c: 函数 `g' :
test004.c:17: エラー: 仮引数 `a' が再宣言されています.
test004.c:15: エラー: ここで宣言されていました.
test004.c:20: エラー: `a' が再宣言されています.
test004.c:19: エラー: ここで宣言されていました.
